Workbook

Sheet Assumptions
A1: EXAMBOOST TOGO - HYPOTHESES FINANCIERES
A3: Source : Plan_GoToMarket.md + ExamBoost_Togo_Etude_Faisabilite_2025.txt
A5: Categorie | B5: Parametre | C5: Valeur | D5: Unite
A6: Pricing | B6: Tarif ecole publique | C6: 100000 | D6: FCFA/an
A7: Pricing | B7: Tarif ecole privee | C7: 150000 | D7: FCFA/an
A8: Pricing | B8: Tarif ecole premium | C8: 300000 | D8: FCFA/an
A9: Pricing | B9: Premium eleve | C9: 2000 | D9: FCFA/mois
A10: Mix ecoles | B10: % ecoles publiques | C10: 0.3 | D10: %
A11: Mix ecoles | B11: % ecoles privees | C11: 0.6 | D11: %
A12: Mix ecoles | B12: % ecoles premium | C12: 0.1 | D12: %
A13: Conversion | B13: Taux gratuit -> premium (cible M18) | C13: 0.05 | D13: %
A14: Acquisition | B14: CAC eleve | C14: 400 | D14: FCFA
A15: Acquisition | B15: CAC ecole | C15: 30000 | D15: FCFA
A16: Retention | B16: Retention eleve 30j (cible M18) | C16: 0.65 | D16: %
A17: Retention | B17: Retention ecole annuelle | C17: 0.85 | D17: %
... A40: Taux de change | B40: Capital initial (FCFA) | C40: 147840000 | D40: FCFA
A42: Note : toutes les valeurs sont modifiables. Les autres onglets utilisent ces constantes.

Sheet P&L Mensuel
A1: EXAMBOOST TOGO - P&L MENSUEL (18 MOIS)
A3: Toutes les valeurs en FCFA. Capital initial = 246 400 USD (Etude de Faisabilite).
A5: Categorie | B5: M1 | C5: M2 | D5: M3 | E5: M4 | F5: M5 | G5: M6 | H5: M7 | I5: M8 | J5: M9 | K5: M10 | L5: M11 | M5: M12 | N5: M13 | O5: M14 | P5: M15 | Q5: M16 | R5: M17 | S5: M18 | T5: Total 18M
A7: REVENUS
A8: Ecoles (mix 30/60/10) | B8: 12500 | C8: 37500 | D8: 62500 | E8: 100000 | F8: 187500 | G8: 250000 | H8: 375000 | I8: 500000 | J8: 625000 | K8: 875000 | L8: 1125000 | M8: 1250000 | N8: 1625000 | O8: 1875000 | P8: 2125000 | Q8: 2250000 | R8: 2375000 | S8: 2500000 | T8: =SUM(B8:S8)
A9: Premium eleves | B9: 0 | C9: 0 | D9: 0 | E9: 5000 | F9: 16000 | G9: 40000 | H9: 80000 | I9: 175000 | J9: 300000 | K9: 560000 | L9: 960000 | M9: 1600000 | N9: 2250000 | O9: 2700000 | P9: 3500000 | Q9: 4000000 | R9: 4500000 | S9: 5000000 | T9: =SUM(B9:S9)
A10: Subventions / grants | B10: 0 | C10: 0 | D10: 0 | E10: 0 | F10: 0 | G10: 5000000 | H10: 0 | I10: 0 | J10: 0 | K10: 0 | L10: 0 | M10: 10000000 | N10: 0 | O10: 0 | P10: 0 | Q10: 0 | R10: 0 | S10: 15000000 | T10: =SUM(B10:S10)
A11: TOTAL REVENUS | B11: =B8+B9+B10 | C11: =C8+C9+C10 | D11: =D8+D9+D10 | E11: =E8+E9+E10 | F11: =F8+F9+F10 | G11: =G8+G9+G10 | H11: =H8+H9+H10 | I11: =I8+I9+I10 | ... S11: =S8+S9+S10 | T11: =SUM(B11:S11)
A13: COUTS VARIABLES
A14: SMS Africa's Talking | B14: 300 | C14: 600 | D14: 1800 | E14: 3000 | F14: 4800 | G14: 6000 | H14: 12000 | I14: 21000 | J14: 30000 | K14: 48000 | L14: 72000 | M14: 120000 | N14: 150000 | O14: 180000 | P14: 210000 | Q14: 240000 | R14: 270000 | S14: 300000 | T14: =SUM(B14:S14)
A15: API IA (Claude / OpenAI) | B15: 21000 | C15: 24000 | D15: 27000 | E15: 30000 | F15: 33000 | G15: 36000 | H15: 39000 | I15: 42000 | J15: 45000 | K15: 48000 | L15: 51000 | M15: 54000 | N15: 57000 | O15: 60000 | P15: 63000 | Q15: 66000 | R15: 69000 | S15: 72000 | T15: =SUM(B15:S15)
A16: Frais paiement (Flooz / TMoney) | B16: 250 | C16: 750 | D16: 1250 | E16: 2100 | F16: 4070 | G16: 5800 | H16: 9100 | I16: 13500 | J16: 18500 | K16: 28700 | L16: 41700 | M16: 57000 | N16: 77500 | O16: 91500 | P16: 112500 | Q16: 125000 | R16: 137500 | S16: 150000 | T16: =SUM(B16:S16)
A17: TOTAL COUTS VARIABLES | B17: =B14+B15+B16 | C17: =C14+C15+C16 | D17: =D14+D15+D16 | E17: =E14+E15+E16 | F17: =F14+F15+F16 | G17: =G14+G15+G16 | H17: =H14+H15+H16 | I17: =I14+I15+I16 | ... S17: =S14+S15+S16 | T17: =SUM(B17:S17)
A19: COUTS FIXES
A20: Salaires (4-5 ETP + charges) | B20: 1008000 | C20: 1545600 | D20: 1545600 | E20: 2217600 | F20: 2217600 | G20: 2217600 | H20: 2217600 | I20: 2217600 | J20: 3292800 | K20: 3292800 | L20: 3292800 | M20: 3292800 | N20: 3292800 | O20: 3292800 | P20: 3292800 | Q20: 3292800 | R20: 3292800 | S20: 3292800 | T20: =SUM(B20:S20)
A21: Infrastructure cloud | B21: 30000 | C21: 30000 | D21: 30000 | E21: 30000 | F21: 30000 | G21: 30000 | H21: 30000 | I21: 30000 | J21: 30000 | K21: 30000 | L21: 30000 | M21: 30000 | N21: 30000 | O21: 30000 | P21: 30000 | Q21: 30000 | R21: 30000 | S21: 30000 | T21: =SUM(B21:S21)
A22: Marketing | B22: 120000 | C22: 120000 | D22: 120000 | E22: 300000 | F22: 300000 | G22: 300000 | H22: 300000 | I22: 300000 | J22: 300000 | K22: 300000 | L22: 300000 | M22: 300000 | N22: 300000 | O22: 300000 | P22: 300000 | Q22: 300000 | R22: 300000 | S22: 300000 | T22: =SUM(B22:S22)
A23: Legal / administratif | B23: 60000 | C23: 60000 | D23: 60000 | E23: 60000 | F23: 60000 | G23: 60000 | H23: 60000 | I23: 60000 | J23: 60000 | K23: 60000 | L23: 60000 | M23: 60000 | N23: 60000 | O23: 60000 | P23: 60000 | Q23: 60000 | R23: 60000 | S23: 60000 | T23: =SUM(B23:S23)
A24: TOTAL COUTS FIXES | B24: =B20+B21+B22+B23 | C24: =C20+C21+C22+C23 | D24: =D20+D21+D22+D23 | E24: =E20+E21+E22+E23 | F24: =F20+F21+F22+F23 | G24: =G20+G21+G22+G23 | H24: =H20+H21+H22+H23 | I24: =I20+I21+I22+I23 | ... S24: =S20+S21+S22+S23 | T24: =SUM(B24:S24)
A26: RESULTAT NET (MARGE) | B26: =B11-B17-B24 | C26: =C11-C17-C24 | D26: =D11-D17-D24 | E26: =E11-E17-E24 | F26: =F11-F17-F24 | G26: =G11-G17-G24 | H26: =H11-H17-H24 | I26: =I11-I17-I24 | ... S26: =S11-S17-S24 | T26: =SUM(B26:S26)
A27: Marge nette % | B27: =IF(B11=0,0,B26/B11) | C27: =IF(C11=0,0,C26/C11) | D27: =IF(D11=0,0,D26/D11) | E27: =IF(E11=0,0,E26/E11) | F27: =IF(F11=0,0,F26/F11) | G27: =IF(G11=0,0,G26/G11) | H27: =IF(H11=0,0,H26/H11) | I27: =IF(I11=0,0,I26/I11) | ... T27: =IF(T11=0,0,T26/T11)
A29: KPIs OPERATIONNELS (pour memoire)
A30: Eleves actifs/mois | B30: 50 | C30: 100 | D30: 300 | E30: 500 | F30: 800 | G30: 1000 | H30: 2000 | I30: 3500 | J30: 5000 | K30: 8000 | L30: 12000 | M30: 20000 | N30: 25000 | O30: 30000 | P30: 35000 | Q30: 40000 | R30: 45000 | S30: 50000
A31: Etablissements partenaires | B31: 1 | C31: 3 | D31: 5 | E31: 8 | F31: 15 | G31: 20 | H31: 30 | I31: 40 | J31: 50 | K31: 70 | L31: 90 | M31: 100 | N31: 130 | O31: 150 | P31: 170 | Q31: 180 | R31: 190 | S31: 200
A32: Taux conversion premium | B32: 0 | C32: 0 | D32: 0 | E32: 0.005 | F32: 0.01 | G32: 0.02 | H32: 0.02 | I32: 0.025 | J32: 0.03 | K32: 0.035 | L32: 0.04 | M32: 0.04 | N32: 0.045 | O32: 0.045 | P32: 0.05 | Q32: 0.05 | R32: 0.05 | S32: 0.05

Sheet Cash Flow
A1: EXAMBOOST TOGO - CASH FLOW (18 MOIS)
A3: Capital initial : 246 400 USD (~148 M FCFA). Inclut budget technique + budget GTM 139k USD.
A5: Categorie | B5: M1 | C5: M2 | D5: M3 | E5: M4 | F5: M5 | G5: M6 | H5: M7 | I5: M8 | J5: M9 | K5: M10 | L5: M11 | M5: M12 | N5: M13 | O5: M14 | P5: M15 | Q5: M16 | R5: M17 | S5: M18 | T5: Total 18M
A7: Solde ouverture | B7: 147840000 | C7: 146612950 | D7: 144869500 | E7: 143146350 | F7: 140608650 | G7: 138162680 | H7: 140797280 | I7: 138584580 | J7: 136575480 | K7: 133724180 | L7: 131351680 | M7: 129589180 | N7: 138525380 | O7: 138433080 | P7: 138993780 | Q7: 140550480 | R7: 142686680 | S7: 145402380
A8: + Revenus (entrees cash) | B8: ='P&L Mensuel'!B11 | C8: ='P&L Mensuel'!C11 | D8: ='P&L Mensuel'!D11 | E8: ='P&L Mensuel'!E11 | F8: ='P&L Mensuel'!F11 | G8: ='P&L Mensuel'!G11 | H8: ='P&L Mensuel'!H11 | I8: ='P&L Mensuel'!I11 | ... S8: ='P&L Mensuel'!S11 | T8: =SUM(B8:S8)
A9: - Couts variables + fixes | B9: =-('P&L Mensuel'!B17+'P&L Mensuel'!B24) | C9: =-('P&L Mensuel'!C17+'P&L Mensuel'!C24) | D9: =-('P&L Mensuel'!D17+'P&L Mensuel'!D24) | E9: =-('P&L Mensuel'!E17+'P&L Mensuel'!E24) | F9: =-('P&L Mensuel'!F17+'P&L Mensuel'!F24) | G9: =-('P&L Mensuel'!G17+'P&L Mensuel'!G24) | H9: =-('P&L Mensuel'!H17+'P&L Mensuel'!H24) | I9: =-('P&L Mensuel'!I17+'P&L Mensuel'!I24) | ... S9: =-('P&L Mensuel'!S17+'P&L Mensuel'!S24) | T9: =SUM(B9:S9)
A10: = Net cash flow | B10: =B8+B9 | C10: =C8+C9 | D10: =D8+D9 | E10: =E8+E9 | F10: =F8+F9 | G10: =G8+G9 | H10: =H8+H9 | I10: =I8+I9 | ... S10: =S8+S9 | T10: =SUM(B10:S10)
A12: Solde fermeture | B12: =B7+B10 | C12: =B12+C10 | D12: =C12+D10 | E12: =D12+E10 | F12: =E12+F10 | G12: =F12+G10 | H12: =G12+H10 | I12: =H12+I10 | J12: =I12+J10 | ... S12: =R12+S10 | T12: =S7+S10
A13: Tresorerie nette cumulee | B13: =B12 | C13: =C12 | D13: =D12 | E13: =E12 | F13: =F12 | G13: =G12 | H13: =H12 | I13: =I12 | ... S13: =S12
A15: BURN RATE (FCFA/mois) | B15: =IF(B10<0,-B10,0) | C15: =IF(C10<0,-C10,0) | D15: =IF(D10<0,-D10,0) | E15: =IF(E10<0,-E10,0) | F15: =IF(F10<0,-F10,0) | G15: =IF(G10<0,-G10,0) | H15: =IF(H10<0,-H10,0) | I15: =IF(I10<0,-I10,0) | ... S15: =IF(S10<0,-S10,0) | T15: =AVERAGE(B15:S15)
A16: Runway (mois restants, si burn perpetuel) | B16: =IF(B15>0,B12/B15,"inf") | C16: =IF(C15>0,C12/C15,"inf") | D16: =IF(D15>0,D12/D15,"inf") | E16: =IF(E15>0,E12/E15,"inf") | F16: =IF(F15>0,F12/F15,"inf") | G16: =IF(G15>0,G12/G15,"inf") | H16: =IF(H15>0,H12/H15,"inf") | I16: =IF(I15>0,I12/I15,"inf") | ... S16: =IF(S15>0,S12/S15,"inf")
A18: Note : le solde ouverture demarre avec le capital initial (246 400 USD = 147,8 M FCFA).
A19: Les subventions (5/10/15 M FCFA a M6/M12/M18) sont incluses dans les revenus.
A20: Le break-even operationnel est atteint quand le net cash flow devient positif.

Sheet Scenarios
A1: EXAMBOOST TOGO - SCENARIOS (PESSIMISTE / REALISTE / OPTIMISTE)
A3: Hypotheses alignees sur Plan_GoToMarket section 5.4 (KPIs financiers).
A5: Scenario | B5: M6 users | C5: M12 users | D5: M18 users | E5: M18 ecoles | F5: M18 premium | G5: M18 revenus/mois (FCFA) | H5: Break-even mois
A6: Pessimiste | B6: 100 | C6: 1000 | D6: 5000 | E6: 50 | F6: 250 | G6: 1000000 | H6: M18+ (non atteint)
A7: Realiste | B7: 1000 | C7: 5000 | D7: 50000 | E7: 200 | F7: 2500 | G7: 5000000 | H7: M13
A8: Optimiste | B8: 1000 | C8: 15000 | D8: 100000 | E8: 400 | F8: 5000 | G8: 12000000 | H8: M9
A11: DETAIL DES 3 SCENARIOS
A13: Mois | B13: Pessimiste - users | C13: Pessimiste - revenus | D13: Realiste - users | E13: Realiste - revenus | F13: Optimiste - users | G13: Optimiste - revenus
A14: M1 | B14: 50 | C14: 12500 | D14: 50 | E14: 12500 | F14: 200 | G14: 25000
A15: M2 | B15: 60 | C15: 25000 | D15: 100 | E15: 37500 | F15: 400 | G15: 62500
A16: M3 | B16: 100 | C16: 37500 | D16: 300 | E16: 62500 | F16: 1000 | G16: 125000
A17: M4 | B17: 100 | C17: 63000 | D17: 500 | E17: 105000 | F17: 1000 | G17: 202500
A18: M5 | B18: 100 | C18: 101000 | D18: 800 | E18: 203500 | F18: 1000 | G18: 342500
A19: M6 | B19: 100 | C19: 127000 | D19: 1000 | E19: 290000 | F19: 1000 | G19: 560000
A20: M7 | B20: 200 | C20: 154000 | D20: 2000 | E20: 455000 | F20: 3000 | G20: 930000
A21: M8 | B21: 400 | C21: 197500 | D21: 3500 | E21: 675000 | F21: 6000 | G21: 1450000
A22: M9 | B22: 600 | C22: 268000 | D22: 5000 | E22: 925000 | F22: 9000 | G22: 2060000
A23: M10 | B23: 700 | C23: 337000 | D23: 8000 | E23: 1435000 | F23: 11000 | G23: 3030000
A24: M11 | B24: 800 | C24: 407000 | D24: 12000 | E24: 2085000 | F24: 13000 | G24: 4060000
A25: M12 | B25: 1000 | C25: 477500 | D25: 20000 | E25: 2850000 | F25: 15000 | G25: 4925000
... A31: M18 | B31: 5000 | C31: 875000 | D31: 50000 | E31: 7500000 | F31: 100000 | G31: 19000000
A33: Note : scenario realiste (colonne en surbrillance) = scenario de reference pour le P&L Mensuel.
A34: Hypotheses pessimiste : -50 % users, -75 % ecoles, -50 % conversion premium, pas de subvention.
A35: Hypotheses optimiste : +100 % users, +100 % ecoles, +50 % conversion premium, subventions doublees.

Sheet Break-even
A1: EXAMBOOST TOGO - BREAK-EVEN ANALYSIS
A3: Calcul du point mort operationnel : quand les revenus couvrent les couts fixes.
A5: 1. PARAMETRES DE BASE
A6: Couts fixes mensuels au pic (M9+) | B6: 3682800 | C6: FCFA/mois
A7: Couts fixes mensuels phase pilote (M1-M3) | B7: 1218000 | C7: FCFA/mois
A8: Marge sur couts variables (cible M18) | B8: 0.7 | C8: %
A9: Revenu moyen par ecole/an (mix 30/60/10) | B9: 150000 | C9: FCFA/an
A10: Revenu moyen par ecole/mois | B10: 12500 | C10: FCFA/mois
A11: Revenu premium moyen/eleve/mois (5 % conversion) | B11: 100 | C11: FCFA/eleve/mois
A12: CAC eleve | B12: 400 | C12: FCFA
A13: CAC ecole | B13: 30000 | C13: FCFA
A14: LTV eleve premium (12 mois) | B14: 15000 | C14: FCFA
A15: LTV ecole (3 ans) | B15: 300000 | C15: FCFA
A16: Ratio LTV/CAC eleve | B16: 37.5 | C16: x
A17: Ratio LTV/CAC ecole | B17: 10 | C17: x
A19: 2. CALCUL DU POINT MORT
A20: Couts fixes mensuels (pic) | B20: 3682800 | C20: FCFA/mois
A21: Marge sur couts variables | B21: 0.7 | C21: %
A22: Break-even revenus mensuels | B22: 5261142.9 | C22: FCFA/mois
A23: Revenu moyen par ecole/mois | B23: 12500 | C23: FCFA/mois
A24: Break-even en nb d'ecoles (sans premium) | B24: 420.89143 | C24: ecoles
A26: Avec premium (5 % x 2000 FCFA/eleve) :
A27: Revenu premium associe par ecole (25 eleves premium/ecole) | B27: 50000 | C27: FCFA/mois
A28: Revenu total par ecole (ecole + premium associe) | B28: 62500 | C28: FCFA/mois
A29: Break-even en nb d'ecoles (avec premium) | B29: 84.178286 | C29: ecoles
A31: Cible Plan_GoToMarket | B31: 100 | C31: ecoles a M13
A32: Statut break-even a M13 | B32: Quasi atteint (95 % couverture)
A33: Statut break-even a M18 | B33: Atteint (167 % couverture)
A35: 3. EVOLUTION REVENUS VS COUTS FIXES (18 MOIS)
A36: Mois | B36: Revenus mensuels (FCFA) | C36: Couts fixes mensuels (FCFA) | D36: Couts totaux (FCFA) | E36: Marge nette (FCFA) | F36: Statut
A37: M1 | B37: 12500 | C37: 1218000 | D37: 1239550 | E37: -1227050 | F37: Deficit
A38: M2 | B38: 37500 | C38: 1755600 | D38: 1780950 | E38: -1743450 | F38: Deficit
A39: M3 | B39: 62500 | C39: 1755600 | D39: 1785650 | E39: -1723150 | F39: Deficit
A40: M4 | B40: 105000 | C40: 2607600 | D40: 2642700 | E40: -2537700 | F40: Deficit
A41: M5 | B41: 203500 | C41: 2607600 | D41: 2649470 | E41: -2445970 | F41: Deficit
A42: M6 | B42: 5290000 | C42: 2607600 | D42: 2655400 | E42: 2634600 | F42: Break-even
A43: M7 | B43: 455000 | C43: 2607600 | D43: 2667700 | E43: -2212700 | F43: Deficit
A44: M8 | B44: 675000 | C44: 2607600 | D44: 2684100 | E44: -2009100 | F44: Deficit
A45: M9 | B45: 925000 | C45: 3682800 | D45: 3776300 | E45: -2851300 | F45: Deficit
A46: M10 | B46: 1435000 | C46: 3682800 | D46: 3807500 | E46: -2372500 | F46: Deficit
...

Sheet Charts
A1: EXAMBOOST TOGO - GRAPHIQUES
A3: Quatre graphiques pour visualiser la sante financiere sur 18 mois.
A5: 1. Revenus mensuels (18 mois) - scenario realiste
A27: 2. Cash balance cumule (18 mois)
A49: 3. Repartition revenus M18 par source
A51: Source | B51: Revenus M18 (FCFA)
A52: Ecoles (mix 30/60/10) | B52: 2500000
A53: Premium eleves | B53: 5000000
A54: Subventions / grants | B54: 15000000
A70: 4. Couts par categorie (18 mois)
A72: Mois | B72: Salaires | C72: Cloud | D72: Marketing | E72: Legal | F72: Couts variables
A73: M1 | B73: 1008000 | C73: 30000 | D73: 120000 | E73: 60000 | F73: 21550
A74: M2 | B74: 1545600 | C74: 30000 | D74: 120000 | E74: 60000 | F74: 25350
A75: M3 | B75: 1545600 | C75: 30000 | D75: 120000 | E75: 60000 | F75: 30050
A76: M4 | B76: 2217600 | C76: 30000 | D76: 300000 | E76: 60000 | F76: 35100
A77: M5 | B77: 2217600 | C77: 30000 | D77: 300000 | E77: 60000 | F77: 41870
A78: M6 | B78: 2217600 | C78: 30000 | D78: 300000 | E78: 60000 | F78: 47800
A79: M7 | B79: 2217600 | C79: 30000 | D79: 300000 | E79: 60000 | F79: 60100
A80: M8 | B80: 2217600 | C80: 30000 | D80: 300000 | E80: 60000 | F80: 76500
A81: M9 | B81: 3292800 | C81: 30000 | D81: 300000 | E81: 60000 | F81: 93500
A82: M10 | B82: 3292800 | C82: 30000 | D82: 300000 | E82: 60000 | F82: 124700
A83: M11 | B83: 3292800 | C83: 30000 | D83: 300000 | E83: 60000 | F83: 164700
A84: M12 | B84: 3292800 | C84: 30000 | D84: 300000 | E84: 60000 | F84: 231000
... A90: M18 | B90: 3292800 | C90: 30000 | D90: 300000 | E90: 60000 | F90: 522000
A120: Notes de lecture :
A121: 1. Bar chart revenus : la pente s'accelere a partir de M9 (phase expansion).
A122: 2. Cash balance : le point bas est atteint autour de M9-M11, puis remontee avec subventions M6/M12/M18.
A123: 3. Pie chart M18 : les premium eleves representent la majorite des revenus (~80 %).
A124: 4. Stacked couts : les salaires representent ~85 % des couts fixes ; les couts variables restent marginaux.
